2018-10-08 09:33:15,450 ERROR: Exception on /dpsk [GET] [in c:\users\intern.nhkhang\appdata\local\programs\python\python37-32\lib\site-packages\flask\app.py:1761]
Traceback (most recent call last):
  File "c:\users\intern.nhkhang\appdata\local\programs\python\python37-32\lib\site-packages\flask\app.py", line 2292, in wsgi_app
    response = self.full_dispatch_request()
  File "c:\users\intern.nhkhang\appdata\local\programs\python\python37-32\lib\site-packages\flask\app.py", line 1815, in full_dispatch_request
    rv = self.handle_user_exception(e)
  File "c:\users\intern.nhkhang\appdata\local\programs\python\python37-32\lib\site-packages\flask\app.py", line 1718, in handle_user_exception
    reraise(exc_type, exc_value, tb)
  File "c:\users\intern.nhkhang\appdata\local\programs\python\python37-32\lib\site-packages\flask\_compat.py", line 35, in reraise
    raise value
  File "c:\users\intern.nhkhang\appdata\local\programs\python\python37-32\lib\site-packages\flask\app.py", line 1813, in full_dispatch_request
    rv = self.dispatch_request()
  File "c:\users\intern.nhkhang\appdata\local\programs\python\python37-32\lib\site-packages\flask\app.py", line 1799, in dispatch_request
    return self.view_functions[rule.endpoint](**req.view_args)
  File "D:\digital-telecommucations\kithuatdieuche\app\routes.py", line 148, in dpsk
    posts = current_user.followed_posts().paginate(
  File "c:\users\intern.nhkhang\appdata\local\programs\python\python37-32\lib\site-packages\werkzeug\local.py", line 347, in __getattr__
    return getattr(self._get_current_object(), name)
AttributeError: 'AnonymousUserMixin' object has no attribute 'followed_posts'
2018-10-08 09:33:22,266 ERROR: Exception on /bpsk [GET] [in c:\users\intern.nhkhang\appdata\local\programs\python\python37-32\lib\site-packages\flask\app.py:1761]
Traceback (most recent call last):
  File "c:\users\intern.nhkhang\appdata\local\programs\python\python37-32\lib\site-packages\flask\app.py", line 2292, in wsgi_app
    response = self.full_dispatch_request()
  File "c:\users\intern.nhkhang\appdata\local\programs\python\python37-32\lib\site-packages\flask\app.py", line 1815, in full_dispatch_request
    rv = self.handle_user_exception(e)
  File "c:\users\intern.nhkhang\appdata\local\programs\python\python37-32\lib\site-packages\flask\app.py", line 1718, in handle_user_exception
    reraise(exc_type, exc_value, tb)
  File "c:\users\intern.nhkhang\appdata\local\programs\python\python37-32\lib\site-packages\flask\_compat.py", line 35, in reraise
    raise value
  File "c:\users\intern.nhkhang\appdata\local\programs\python\python37-32\lib\site-packages\flask\app.py", line 1813, in full_dispatch_request
    rv = self.dispatch_request()
  File "c:\users\intern.nhkhang\appdata\local\programs\python\python37-32\lib\site-packages\flask\app.py", line 1799, in dispatch_request
    return self.view_functions[rule.endpoint](**req.view_args)
  File "D:\digital-telecommucations\kithuatdieuche\app\routes.py", line 96, in bpsk
    says = current_user.followed_says().paginate(
  File "c:\users\intern.nhkhang\appdata\local\programs\python\python37-32\lib\site-packages\werkzeug\local.py", line 347, in __getattr__
    return getattr(self._get_current_object(), name)
AttributeError: 'AnonymousUserMixin' object has no attribute 'followed_says'
2018-10-08 09:33:23,329 ERROR: Exception on /dpsk [GET] [in c:\users\intern.nhkhang\appdata\local\programs\python\python37-32\lib\site-packages\flask\app.py:1761]
Traceback (most recent call last):
  File "c:\users\intern.nhkhang\appdata\local\programs\python\python37-32\lib\site-packages\flask\app.py", line 2292, in wsgi_app
    response = self.full_dispatch_request()
  File "c:\users\intern.nhkhang\appdata\local\programs\python\python37-32\lib\site-packages\flask\app.py", line 1815, in full_dispatch_request
    rv = self.handle_user_exception(e)
  File "c:\users\intern.nhkhang\appdata\local\programs\python\python37-32\lib\site-packages\flask\app.py", line 1718, in handle_user_exception
    reraise(exc_type, exc_value, tb)
  File "c:\users\intern.nhkhang\appdata\local\programs\python\python37-32\lib\site-packages\flask\_compat.py", line 35, in reraise
    raise value
  File "c:\users\intern.nhkhang\appdata\local\programs\python\python37-32\lib\site-packages\flask\app.py", line 1813, in full_dispatch_request
    rv = self.dispatch_request()
  File "c:\users\intern.nhkhang\appdata\local\programs\python\python37-32\lib\site-packages\flask\app.py", line 1799, in dispatch_request
    return self.view_functions[rule.endpoint](**req.view_args)
  File "D:\digital-telecommucations\kithuatdieuche\app\routes.py", line 148, in dpsk
    posts = current_user.followed_posts().paginate(
  File "c:\users\intern.nhkhang\appdata\local\programs\python\python37-32\lib\site-packages\werkzeug\local.py", line 347, in __getattr__
    return getattr(self._get_current_object(), name)
AttributeError: 'AnonymousUserMixin' object has no attribute 'followed_posts'
2018-10-08 09:33:24,313 ERROR: Exception on /dpsk [GET] [in c:\users\intern.nhkhang\appdata\local\programs\python\python37-32\lib\site-packages\flask\app.py:1761]
Traceback (most recent call last):
  File "c:\users\intern.nhkhang\appdata\local\programs\python\python37-32\lib\site-packages\flask\app.py", line 2292, in wsgi_app
    response = self.full_dispatch_request()
  File "c:\users\intern.nhkhang\appdata\local\programs\python\python37-32\lib\site-packages\flask\app.py", line 1815, in full_dispatch_request
    rv = self.handle_user_exception(e)
  File "c:\users\intern.nhkhang\appdata\local\programs\python\python37-32\lib\site-packages\flask\app.py", line 1718, in handle_user_exception
    reraise(exc_type, exc_value, tb)
  File "c:\users\intern.nhkhang\appdata\local\programs\python\python37-32\lib\site-packages\flask\_compat.py", line 35, in reraise
    raise value
  File "c:\users\intern.nhkhang\appdata\local\programs\python\python37-32\lib\site-packages\flask\app.py", line 1813, in full_dispatch_request
    rv = self.dispatch_request()
  File "c:\users\intern.nhkhang\appdata\local\programs\python\python37-32\lib\site-packages\flask\app.py", line 1799, in dispatch_request
    return self.view_functions[rule.endpoint](**req.view_args)
  File "D:\digital-telecommucations\kithuatdieuche\app\routes.py", line 148, in dpsk
    posts = current_user.followed_posts().paginate(
  File "c:\users\intern.nhkhang\appdata\local\programs\python\python37-32\lib\site-packages\werkzeug\local.py", line 347, in __getattr__
    return getattr(self._get_current_object(), name)
AttributeError: 'AnonymousUserMixin' object has no attribute 'followed_posts'
2018-10-08 09:33:25,157 ERROR: Exception on /bpsk [GET] [in c:\users\intern.nhkhang\appdata\local\programs\python\python37-32\lib\site-packages\flask\app.py:1761]
Traceback (most recent call last):
  File "c:\users\intern.nhkhang\appdata\local\programs\python\python37-32\lib\site-packages\flask\app.py", line 2292, in wsgi_app
    response = self.full_dispatch_request()
  File "c:\users\intern.nhkhang\appdata\local\programs\python\python37-32\lib\site-packages\flask\app.py", line 1815, in full_dispatch_request
    rv = self.handle_user_exception(e)
  File "c:\users\intern.nhkhang\appdata\local\programs\python\python37-32\lib\site-packages\flask\app.py", line 1718, in handle_user_exception
    reraise(exc_type, exc_value, tb)
  File "c:\users\intern.nhkhang\appdata\local\programs\python\python37-32\lib\site-packages\flask\_compat.py", line 35, in reraise
    raise value
  File "c:\users\intern.nhkhang\appdata\local\programs\python\python37-32\lib\site-packages\flask\app.py", line 1813, in full_dispatch_request
    rv = self.dispatch_request()
  File "c:\users\intern.nhkhang\appdata\local\programs\python\python37-32\lib\site-packages\flask\app.py", line 1799, in dispatch_request
    return self.view_functions[rule.endpoint](**req.view_args)
  File "D:\digital-telecommucations\kithuatdieuche\app\routes.py", line 96, in bpsk
    says = current_user.followed_says().paginate(
  File "c:\users\intern.nhkhang\appdata\local\programs\python\python37-32\lib\site-packages\werkzeug\local.py", line 347, in __getattr__
    return getattr(self._get_current_object(), name)
AttributeError: 'AnonymousUserMixin' object has no attribute 'followed_says'
2018-10-08 09:33:37,423 ERROR: Exception on /bpsk [GET] [in c:\users\intern.nhkhang\appdata\local\programs\python\python37-32\lib\site-packages\flask\app.py:1761]
Traceback (most recent call last):
  File "c:\users\intern.nhkhang\appdata\local\programs\python\python37-32\lib\site-packages\flask\app.py", line 2292, in wsgi_app
    response = self.full_dispatch_request()
  File "c:\users\intern.nhkhang\appdata\local\programs\python\python37-32\lib\site-packages\flask\app.py", line 1815, in full_dispatch_request
    rv = self.handle_user_exception(e)
  File "c:\users\intern.nhkhang\appdata\local\programs\python\python37-32\lib\site-packages\flask\app.py", line 1718, in handle_user_exception
    reraise(exc_type, exc_value, tb)
  File "c:\users\intern.nhkhang\appdata\local\programs\python\python37-32\lib\site-packages\flask\_compat.py", line 35, in reraise
    raise value
  File "c:\users\intern.nhkhang\appdata\local\programs\python\python37-32\lib\site-packages\flask\app.py", line 1813, in full_dispatch_request
    rv = self.dispatch_request()
  File "c:\users\intern.nhkhang\appdata\local\programs\python\python37-32\lib\site-packages\flask\app.py", line 1799, in dispatch_request
    return self.view_functions[rule.endpoint](**req.view_args)
  File "D:\digital-telecommucations\kithuatdieuche\app\routes.py", line 96, in bpsk
    says = current_user.followed_says().paginate(
  File "c:\users\intern.nhkhang\appdata\local\programs\python\python37-32\lib\site-packages\werkzeug\local.py", line 347, in __getattr__
    return getattr(self._get_current_object(), name)
AttributeError: 'AnonymousUserMixin' object has no attribute 'followed_says'
